Workbook

Sheet Parameters
A1: Probability | B1: Mean | C1: StdDev
A2: 0.92230872 | B2: 45 | C2: 11.23

Sheet Data
A1: Age | B1: Group
A2: 74.05808 | B2: 1
A3: 45.8556 | B3: 4
A4: 34.523503 | B4: 2
A5: 52.515912 | B5: 4
A6: 40.41329 | B6: 4
A7: 43.144038 | B7: 3
A8: 41.653946 | B8: 2
A9: 30.734545 | B9: 3
A10: 35.699452 | B10: 2
A11: 62.257854 | B11: 2
A12: 49.09623 | B12: 2
A13: 29.089784 | B13: 4
... A251: 33.804908 | B251: 2

Sheet Sample
A1: Age | B1: Group | C1: Sample
A2: 74.05808 | B2: 1 | C2: =IF(B2=1,A2," ") -> 74.05808
A3: 45.8556 | B3: 4 | C3: =IF(B3=1,A3," ")
A4: 34.523503 | B4: 2 | C4: =IF(B4=1,A4," ")
A5: 52.515912 | B5: 4 | C5: =IF(B5=1,A5," ")
A6: 40.41329 | B6: 4 | C6: =IF(B6=1,A6," ")
A7: 43.144038 | B7: 3 | C7: =IF(B7=1,A7," ")
A8: 41.653946 | B8: 2 | C8: =IF(B8=1,A8," ")
A9: 30.734545 | B9: 3 | C9: =IF(B9=1,A9," ")
A10: 35.699452 | B10: 2 | C10: =IF(B10=1,A10," ")
A11: 62.257854 | B11: 2 | C11: =IF(B11=1,A11," ")
A12: 49.09623 | B12: 2 | C12: =IF(B12=1,A12," ")
A13: 29.089784 | B13: 4 | C13: =IF(B13=1,A13," ")
... A251: 33.804908 | B251: 2 | C251: =IF(B251=1,A251," ")

Sheet Statistical Insight
A2: Std Dev (Sample) | B2: =SQRT(_xlfn.VAR.S(Sample!C2:C251)) -> 10.837175 | D2: Numerosità campionaria: il campione è stato estratto casualmente ed ha numerosità di 62 elementi. Tale valore consentirebbe tranquillamente l'utilizzo di una Distribuzione Normale, in quanto risulta già ben oltre la soglia minima di rappresentatività di 30 elementi. Media campionaria: la media campionaria calcolata è di 44,27, valore molto vicino alla media della popolazione totale, ovvero 45 anni. Tale stima porta già inizialmente a considerare il campione come ben rappresentativo della popolazione. Infatti solo dalla numerosità campionaria non era possibile stabilire la bontà dei dati. Deviazione Standard campionaria: la standard deviation del campione si calcola come la radice quadrata della varianza campionaria. E' pari a 10,84, anche in questo caso molto vicino alla deviazione standard della popolazione, ovvero 10,62. Intervallo di confidenza: dallo studio emerge che, con una confidenza del 95%, possiamo stimare che la vera media si collochi all'interno dell'intervallo di età 40,92 - 46,21. In effetti, la media della popolazione è 45 e tale valore è perfettamente all'interno dell'intervallo calcolato. Confidence rate: si è scelto un tasso di confidenza pari a 0,95, con conseguente alpha pari a 1-0,95 = 0,05. Tali valori sono stati scelti di default, sulla base di una convezione che suggerisce che queste percentuali possano essere tra le migliori per assicurare una stima quanto più aderente al vero valore, o quantomento che consenta di lavorare con valori verosimili. P-value: per valutare il valore emerso del p-value, è necessario fare un excurcusus sulle ipotesi scelte. Infatti, la verifica sarà da fare sulle seguenti ipotesi: - H0 : x̅ = μ - H1 : x̅ ≠ μ Dal calcolo del p-value, abbiamo ricavato il valore 0,827, che risulta essere significativamente maggiore dell'indice Alpha di 0,05. Quanto emerso ci porta ad accettare l'ipotesi nulla H0 e a dichiarare con un ottimo livello di significatività che la media campionaria è rappresentativa della popolazione.
A3: Count (Sample) | B3: =COUNT(Sample!C2:C251) -> 62
A4: Expected Value (Sample) | B4: =AVERAGE(Sample!C2:C63) -> 43.565405
A5: Popolation variance | B5: =_xlfn.VAR.P(Data!A2:A251) -> 112.87857
A6: Population Std Dev | B6: =SQRT(B5) -> 10.624433
A7: Standard error | B7: =B6/SQRT(B3) -> 1.3493043
A8: Confidence Rate | B8: 0.95
A9: Alpha | B9: =1-B8 -> 0.05
A10: Z-score | B10: =_xlfn.NORM.S.INV(0.975) -> 1.959964
A11: Confidence Interval (Lower) | B11: =B4-(B10*B7) -> 40.920817
A12: Confidence Interval (Upper) | B12: =B4+(B10*B7) -> 46.209993
A13: Estimation of p-parameter | B13: =2*MIN(_xlfn.Z.TEST(Sample!C2:C251,AVERAGE(Sample!A2:A251),SQRT(_xlfn.VAR.P(Sample!A2:A251))),1-_xlfn.Z.TEST(Sample!C2:C251,AVERAGE(Sample!A2:A251),SQRT(_xlfn.VAR.P(Sample!A2:A251)))) -> 0.82725251

Sheet (Un)correlated Variables
A1: Sample data | B1: Number of cats | C1: Age of partner
A2: 74.05808 | B2: 5 | C2: 48 | O2: Covarianza | P2: =_xlfn.COVARIANCE.S(A2:A63,B2:B63) -> -2.3024714
A3: 41.264322 | B3: 1 | C3: 34 | O3: Pearson | P3: =PEARSON(A2:A63,B2:B63) -> -0.12284289
A4: 47.419485 | B4: 4 | C4: 40
A5: 44.539428 | B5: 2 | C5: 51 | O5: Diversi sono i fatttori che ci fanno intuire che la correlazione tra le variabili "Età del campione" e "Numero di gatti" è molto bassa (praticamente inesistente) e, se proprio dobbiamo darle un verso, risulta essere quello negativo. Dal grafico è evidente come i dots non seguano una direzione precisa e si spargano in maniera abbastanza uniforme lungo il grafico, mantenendo distanze casuali dalla retta di regressione. La retta, invece, segue una traiettoria leggermente negativa. Queste due informazioni sono perfettamente rappresentate dal Coefficiente di Pearson, che assume valore -0,12284: esso ci indica con il segno meno che ci stiamo interfacciando con una correlazione negativa - pertanto all'aumentare dell'età diminuiranno il numero di gatti (e viceversa) - ma soprattutto con una correlazione molto debole e quasi prossima allo 0. Tali risultati ci portano a dire che le due variabili sono quasi incorrelate o se lo sono, è un legame estramente debole e poco degno di nota.
A6: 38.322041 | B6: 2 | C6: 50
A7: 46.400956 | B7: 5 | C7: 49
A8: 47.259859 | B8: 5 | C8: 44
A9: 26.783504 | B9: 1 | C9: 49
A10: 38.298057 | B10: 3 | C10: 78
A11: 33.398128 | B11: 5 | C11: 79
A12: 45.358944 | B12: 0 | C12: 59
A13: 50.63262 | B13: 4 | C13: 58
A14: 31.422227 | B14: 2 | C14: 33
A15: 44.758018 | B15: 4 | C15: 66
A16: 55.775017 | B16: 1 | C16: 51
A17: 47.53983 | B17: 2 | C17: 80
... A22: 45.807149 | B22: 3 | C22: 54
A23: 54.41711 | B23: 0 | C23: 23 | O23: Covarianza | P23: =_xlfn.COVARIANCE.S(A2:A63,C2:C63) -> -38.626699
A24: 22.795715 | B24: 3 | C24: 50 | O24: Pearson | P24: =PEARSON(A2:A63,C2:C63) -> -0.20852579
A25: 47.065536 | B25: 0 | C25: 60
A26: 38.91386 | B26: 2 | C26: 73
A27: 40.275146 | B27: 0 | C27: 21 | O27: Anche in questo caso è possibile osservare uno stato di non correlazione tra le due variabili, reso evidente, come nel caso del numero di gatti, sia dal grafico, sia dallo coefficiente di correlazione di Pearson: - dal grafico è possibile notare una distribuzione casuale dei punti, assolutamente incoerenti con la retta di regressione che si è venuta a creare. Tale retta ci restituisce una piccola informazione, ossia che la debole correlazione che si è venuta a creare ha carattere negativo - al diminuire dell'età del campione, aumenta l'età del partner. - il coeffiente di Pearson ricavato, ovvero -0,20853, riassume benissimo le due informazioni restituite anche dal grafico, ovvero una correlazione molto molto debole, quasi nulla e una caratterizzazione negativa.
A28: 46.295952 | B28: 1 | C28: 21
A29: 24.251851 | B29: 0 | C29: 35
A30: 48.114629 | B30: 2 | C30: 77
A31: 53.901289 | B31: 0 | C31: 32
A32: 41.966891 | B32: 4 | C32: 44
A33: 63.230234 | B33: 5 | C33: 23
A34: 58.315436 | B34: 2 | C34: 37
A35: 53.211086 | B35: 1 | C35: 36
A36: 48.239722 | B36: 4 | C36: 51
A37: 45.582865 | B37: 5 | C37: 59
A38: 62.634354 | B38: 1 | C38: 65
A39: 43.145386 | B39: 4 | C39: 66
... A42: 46.802318 | B42: 0 | C42: 77
A43: 25.083311 | B43: 2 | C43: 62 | F43: In entrambi i casi, il valore di R2 è molto prossimo allo 0 (0,0151 nel primo caso e 0,0435 nel secondo). R2 si chiama coefficiente di determinazione e serve a capire quanto il modello utilizzato è adatto a spiegare la variabilità dei dati. In questo caso, nessuno dei due modelli spiega bene i dati, in quanto questi sono incorrelati e non è praticamente possibile identificare un modello coerente. In sostanza, il modello non spiega i dati perchè i dati non sono correlati.
A44: 44.128608 | B44: 5 | C44: 69
A45: 61.186052 | B45: 0 | C45: 62
A46: 32.044499 | B46: 2 | C46: 60
...

Sheet Linear Regression
A1: Y (age) | B1: X (rank) | D1: Previsione (160)
A2: 74.05808 | B2: 1 | D2: =_xlfn.FORECAST.LINEAR(160,A2:A251,B2:B251) -> 44.153682
A3: 45.8556 | B3: 2
A4: 34.523503 | B4: 3
A5: 52.515912 | B5: 4
A6: 40.41329 | B6: 5
A7: 43.144038 | B7: 6
A8: 41.653946 | B8: 7
A9: 30.734545 | B9: 8
A10: 35.699452 | B10: 9
A11: 62.257854 | B11: 10
A12: 49.09623 | B12: 11
A13: 29.089784 | B13: 12
A14: 36.060628 | B14: 13
... A251: 33.804908 | B251: 250
